<mujoco model="ur5e">
  <compiler angle="radian" meshdir="meshes" autolimits="true"/>
  <option timestep="0.001"/>

  <default>
    <default class="ur5e">
      <material specular="0.5" shininess="0.25"/>
      <!-- <joint axis="0 1 0" range="-6.28319 6.28319" armature="0.1"/>
      <general gaintype="fixed" biastype="affine" ctrlrange="-6.2831 6.2831" gainprm="2000" biasprm="0 -2000 -400"
        forcerange="-150 150"/> -->
      <default class="visual">
        <geom type="mesh" contype="0" conaffinity="0" group="2"/>
      </default>
      <default class="collision">
        <geom type="capsule" group="3"/>
        <default class="eef_collision">
          <geom type="cylinder"/>
        </default>
      </default>
      <default class="racket_collision">
        <!-- 1000 and 0111 -->
        <geom contype="8" conaffinity="7"  group="3"/>
      </default>
      <!-- <site size="0.001" rgba="0.5 0.5 0.5 0.3" group="4"/> -->
      <default class="Shoulder">
        <motor ctrlrange="-1.485 1.485" user="3030 2000 1.87e-8"/>
      </default>      
      <default class="Wrist">
        <motor ctrlrange="-0.277 0.277" user="3030 2000 2.07e-5"/>
      </default>
    </default>
  </default>
  

  <asset>
    <material class="ur5e" name="black" rgba="0.033 0.033 0.033 1"/>
    <material class="ur5e" name="jointgray" rgba="0.278 0.278 0.278 1"/>
    <material class="ur5e" name="linkgray" rgba="0.82 0.82 0.82 1"/>
    <material class="ur5e" name="urblue" rgba="0.49 0.678 0.8 1"/>

    <mesh file="base_0.obj"/>
    <mesh file="base_1.obj"/>
    <mesh file="shoulder_0.obj"/>
    <mesh file="shoulder_1.obj"/>
    <mesh file="shoulder_2.obj"/>
    <mesh file="upperarm_0.obj"/>
    <mesh file="upperarm_1.obj"/>
    <mesh file="upperarm_2.obj"/>
    <mesh file="upperarm_3.obj"/>
    <mesh file="forearm_0.obj"/>
    <mesh file="forearm_1.obj"/>
    <mesh file="forearm_2.obj"/>
    <mesh file="forearm_3.obj"/>
    <mesh file="wrist1_0.obj"/>
    <mesh file="wrist1_1.obj"/>
    <mesh file="wrist1_2.obj"/>
    <mesh file="wrist2_0.obj"/>
    <mesh file="wrist2_1.obj"/>
    <mesh file="wrist2_2.obj"/>
    <mesh file="wrist3.obj"/>
    <mesh file="racket.STL"/>
  </asset>

  <worldbody>
    <!-- <light name="spotlight" mode="targetbodycom" target="wrist_2_link" pos="0 -1 2"/> -->
    <light name="spotlight" mode="track" pos="0 0 3" dir="0 0 -1"  castshadow="false"/>
    <light name="front" mode="track" pos="3 0.2 1.5" dir="-1 0 0" castshadow="false"/>
    <body name="base" pos="0 -0.24 0.7" quat="1 -1 0 0" childclass="ur5e">
      <inertial mass="4.0" pos="0 0 0" diaginertia="0.00443333156 0.00443333156 0.0072"/>
      <geom mesh="base_0" material="black" class="visual"/>
      <geom mesh="base_1" material="jointgray" class="visual"/>
      <body name="shoulder_link" pos="0 0 0.163" quat="1 0 0 1">
        <inertial mass="3.7" pos="0 0 0" diaginertia="0.0102675 0.0102675 0.00666"/>
        <joint name="ShoulderRoll" axis="0 0 1" range="-3.1415 3.1415"  limited="true"/>
        <geom mesh="shoulder_0" material="urblue" class="visual"/>
        <geom mesh="shoulder_1" material="black" class="visual"/>
        <geom mesh="shoulder_2" material="jointgray" class="visual"/>
        <geom class="collision" size="0.06 0.06" pos="0 0 -0.04"/>
        <body name="upper_arm_link" pos="0 0.138 0" quat="1 0 1 0">
          <inertial mass="8.393" pos="0 0 0.2125" diaginertia="0.133886 0.133886 0.0151074"/>
          <joint name="ShoulderPitch" axis="0 -1 0" range="-3.1415 4.8"  limited="true"/>
          <geom mesh="upperarm_0" material="linkgray" class="visual"/>
          <geom mesh="upperarm_1" material="black" class="visual"/>
          <geom mesh="upperarm_2" material="jointgray" class="visual"/>
          <geom mesh="upperarm_3" material="urblue" class="visual"/>
          <geom class="collision" pos="0 -0.04 0" quat="1 1 0 0" size="0.06 0.06"/>
          <geom class="collision" size="0.05 0.2" pos="0 0 0.2"/>
          <body name="forearm_link" pos="0 -0.131 0.425">
            <inertial mass="2.275" pos="0 0 0.196" diaginertia="0.0311796 0.0311796 0.004095"/>
            <joint name="Elbow" axis="0 -1 0" range="-3.1415 3.14"  limited="true"/>
            <geom mesh="forearm_0" material="urblue" class="visual"/>
            <geom mesh="forearm_1" material="linkgray" class="visual"/>
            <geom mesh="forearm_2" material="black" class="visual"/>
            <geom mesh="forearm_3" material="jointgray" class="visual"/>
            <geom class="collision" pos="0 0.08 0" quat="1 1 0 0" size="0.055 0.06"/>
            <geom class="collision" size="0.038 0.19" pos="0 0 0.2"/>
            <body name="wrist_1_link" pos="0 0 0.392" quat="1 0 1 0">
              <inertial mass="1.219" pos="0 0.127 0" diaginertia="0.0025599 0.0025599 0.0021942"/>
              <joint name="wrist_1" axis="0 -1 0" range="-3.1415 3.14"  limited="true"/>
              <geom mesh="wrist1_0" material="black" class="visual"/>
              <geom mesh="wrist1_1" material="urblue" class="visual"/>
              <geom mesh="wrist1_2" material="jointgray" class="visual"/>
              <geom class="collision" pos="0 0.05 0" quat="1 1 0 0" size="0.04 0.07"/>
              <body name="wrist_2_link" pos="0 0.127 0" quat="1 0 0 1">
                <inertial mass="1.219" pos="0 0 0.1" diaginertia="0.0025599 0.0025599 0.0021942"/>
                <joint name="wrist_2" axis="0 0 1" range="-3.1415 3.14"  limited="true"/>
                <geom mesh="wrist2_0" material="black" class="visual"/>
                <geom mesh="wrist2_1" material="urblue" class="visual"/>
                <geom mesh="wrist2_2" material="jointgray" class="visual"/>
                <geom class="collision" size="0.04 0.06" pos="0 0 0.04"/>
                <geom class="collision" pos="0 0.02 0.1" quat="1 1 0 0" size="0.04 0.04"/>
                <body name="wrist_3_link" pos="0 0 0.1" quat="1 1 0 0">
                  <!-- <inertial mass="0.1889" pos="0 0.0771683 0" quat="1 0 0 1"
                    diaginertia="0.000132134 9.90863e-05 9.90863e-05"/> -->
                  <!-- <joint name="wrist_3" axis="0 -1 0" range="-3.1415 3.14"  limited="true"/>
                  <geom material="linkgray" mesh="wrist3" class="visual"/>
                  <geom class="eef_collision" pos="0 0.08 0" quat="1 1 0 0" size="0.04 0.02"/>
                  <site name="attachment_site" pos="0 0.1 0" quat="-1 1 0 0"/> -->
                
                  <joint name="wrist_3" axis="0 -1 0" range="-3.1415 3.14"  limited="true"/>
                  <geom material="linkgray" mesh="racket" class="visual" pos = "0 0 0"/>
                  <geom class="racket_collision" name="racket1" type="cylinder" size="0.01 0.2" pos="0.0 0.0 -0.22"/>
                  <site name="HandIMU" size="0.01" pos="0 0 0.0" group="0"/>
                  <site name="EndIMU" size="0.01" pos="0 0 -0.54" group="0"/>
                  <geom class="racket_collision" name="racket2" type="cylinder" size="0.085 0.06" pos="0 -0.06 -0.54" euler="1.57 0 0"  friction="0.8 0.8 0.8"/>
                  <inertial pos="0.0 0.0 -0.35" mass="0.09"  diaginertia="0.004425  0.004448  0.000227"/> 
                </body>
              </body>
            </body>
          </body>
        </body>
      </body>
    </body>
  </worldbody>

  <actuator>
    <motor class="Shoulder" name="ShoulderRoll" joint="ShoulderRoll" gear="101"/>
    <motor class="Shoulder" name="ShoulderPitch" joint="ShoulderPitch" gear="101"/>
    <motor class="Shoulder" name="Elbow" joint="Elbow" gear="101"/>
    <motor class="Wrist" name="wrist_1" joint="wrist_1" gear="101"/>
    <motor class="Wrist" name="wrist_2" joint="wrist_2" gear="101"/>
    <motor class="Wrist" name="wrist_3" joint="wrist_3" gear="101"/>

    <!-- <general class="Shoulder" name="ShoulderRoll" joint="ShoulderRoll"/>
    <general class="Shoulder" name="ShoulderPitch" joint="ShoulderPitch"/>
    <general class="Shoulder" name="Elbow" joint="Elbow"/>
    <general class="Wrist" name="wrist_1" joint="wrist_1"/>
    <general class="Wrist" name="wrist_2" joint="wrist_2"/>
    <general class="Wrist" name="wrist_3" joint="wrist_3"/> -->
  </actuator>

  <sensor>
    <accelerometer name="HnadAcc" site="HandIMU" noise="1e-2"/>
    <gyro name="HandGyro" site="HandIMU" noise="5e-4"/>
    <velocimeter name="HandVel" site="HandIMU" noise="5e-4"/>
    
    <accelerometer name="EndAcc" site="EndIMU" noise="1e-2"/>
    <gyro name="EndGyro" site="EndIMU" noise="5e-4"/>
    <velocimeter name="EndVel" site="EndIMU" noise="5e-4"/>
    <touch name="EndTouch" site="EndIMU"/>
  </sensor>

  <!-- <keyframe>
    <key name="home" qpos="0.0 0.0 0.0 0.0 0.0 0.0" ctrl="-1.5708 -1.5708 1.5708 -1.5708 -1.5708 0"/>
  </keyframe> -->
</mujoco>
